<?xml version="1.0" encoding="utf-8"?>
<robot name="eddiebot" xmlns:xacro="http://ros.org/wiki/xacro">
  <xacro:include filename="inertial_macros.xacro"/>
  <xacro:include filename="common_properties.xacro"/>


  <link name="base_footprint"/>
 
  <joint name="odom_joint" type="fixed">
    <parent link="odom"/>
    <child link="base_footprint"/>
    <origin xyz="0 0 0" rpy="0 0 0"/>
  </joint>
  <link name="odom"/>

  <link name="base_link" >
    <inertial>
      <origin
        xyz="6.40516959288934E-06 9.88983228679408E-08 0.0234596082010042"
        rpy="0 0 0" />
      <mass value="1.958" />
      <inertia
        ixx="0.01950247"
        ixy="0.0"
        ixz="-0.00020457"
        iyy="0.02561711"
        iyz="0.0"
        izz="0.04157802" />
    </inertial>
    <visual>
      <origin
        xyz="0 0 0"
        rpy="0 0 0" />
      <geometry>
        <mesh
          filename="package://eddiebot_gazebo/meshes/base_link.STL" />
      </geometry>
      <material name="light_black"/>
    </visual>
    <collision>
      <origin
        xyz="0 0 0"
        rpy="0 0 0" />
      <geometry>
        <box size="0.174 0.368 0.0762"/>
      </geometry>
    </collision>
  </link>
  <joint name="base_joint"
    type="fixed">
    <origin
      xyz="-0.00188188452335199 -0.000513601526006199 0.0670000000013061"
      rpy="0 0 0" />
    <parent
      link="base_footprint" />
    <child
      link="base_link" />
    <axis
      xyz="0 0 0" />
  </joint>
  <link name="base_top_link">
    <inertial>
      <origin
        xyz="0.000307130677125385 1.10241172166653E-07 0.134982649934056"
        rpy="0 0 0" />
      <mass
        value="1.724" />
      <inertia
        ixx="0.02119577"
        ixy="0.0"
        ixz="8.22e-06"
        iyy="0.02278843"
        iyz="0"
        izz="0.04313801" />
    </inertial>
    <visual>
      <origin
        xyz="0 0 0"
        rpy="0 0 0" />
      <geometry>
        <mesh
          filename="package://eddiebot_gazebo/meshes/base_top_link.STL" />
      </geometry>
      <material name="light_black"/>
    </visual>
    <collision>
      <origin
        xyz="0.015 0 0.07"
        rpy="0 0 0" />
      <geometry>
        <cylinder length="0.1356" radius="0.223"/>
      </geometry>
    </collision>
  </link>
  <joint name="base_top_joint"
    type="fixed">
    <origin
      xyz="-0.00879392436820687 0 0.03665"
      rpy="0 0 0" />
    <parent
      link="base_link" />
    <child
      link="base_top_link" />
    <axis
      xyz="0 0 0" />
  </joint>
  <link name="kinect_plate_link">
    <inertial>
      <origin
        xyz="-0.00741329248753544 -0.00100077555843242 0.219296009980792"
        rpy="0 0 0" />
      <mass
        value="0.272"/>
      <inertia
        ixx="0.00414787"
        ixy="-1e-08"
        ixz="0.00018088"
        iyy="0.00286104"
        iyz="2e-08"
        izz="0.00139722" />
    </inertial>
    <visual>
      <origin
        xyz="0 0 0"
        rpy="0 0 0" />
      <geometry>
        <mesh
          filename="package://eddiebot_gazebo/meshes/kinect_plate_link.STL" />
      </geometry>
      <material name="light_black"/>
    </visual>
    <collision>
      <origin
        xyz="0 0 0.15"
        rpy="0 0 0" />
      <geometry>
        <box size="0.065 0.188 0.310"/>
      </geometry>
    </collision>
  </link>
  <joint name="kinect_plate_joint"
    type="fixed">
    <origin
      xyz="-0.145492267835786 0.000999999997519332 0.1406"
      rpy="0 0 0" />
    <parent
      link="base_top_link" />
    <child
      link="kinect_plate_link" />
    <axis
      xyz="0 0 0" />
  </joint>
  <link name="motor_right_link">
    <inertial>
      <origin
        xyz="-9.69481684120234E-05 6.09797385771327E-05 0.0406295446299301"
        rpy="0 0 0" />
      <mass
        value="1.046" />
      <inertia
        ixx="0.00121916"
        ixy="-0.00026888"
        ixz="0.000388"
        iyy="0.00203021"
        iyz="0.00015076"
        izz="0.00209411" />
    </inertial>
    <visual>
      <origin
        xyz="0 0 0"
        rpy="0 0 0" />
      <geometry>
        <mesh
          filename="package://eddiebot_gazebo/meshes/motor_right_link.STL" />
      </geometry>
      
      <material name ="orange"/>
    </visual>
  </link>
  <joint name="motor_right_joint"
    type="fixed">
    <origin
      xyz="-0.02 -0.13727 -0.0320000000013062"
      rpy="0 0 0" />
    <parent
      link="base_link" />
    <child
      link="motor_right_link" />
    <axis
      xyz="0 0 0" />
  </joint>
 
  <link name="motor_left_link">
    <inertial>
      <origin
        xyz="-6.94825791193628E-06 -1.6822235779354E-05 0.0406295391896895"
        rpy="0 0 0" />
      <mass
        value="1.046" />
      <inertia
        ixx="0.00121916"
        ixy="0.00026888"
        ixz="-0.000388"
        iyy="0.00203021"
        iyz="0.00015076"
        izz="0.00209411" />
      </inertial>
      <visual>
      <origin
        xyz="0 0 0"
        rpy="0 0 0" />
      <geometry>
        <mesh
          filename="package://eddiebot_gazebo/meshes/motor_left_link.STL" />
      </geometry>
      <geometry>
        <cylinder radius="0.0765" length="0.0304"/>
      </geometry>
      <material name ="orange"/>
    </visual>
  </link>
  <joint name="motor_left_joint"
    type="fixed">
    <origin
      xyz="-0.02009 0.13727 -0.032"
      rpy="0 0 0" />
    <parent
      link="base_link" />
    <child
      link="motor_left_link" />
    <axis
      xyz="0 0 0" />
  </joint>
  
  <link name="battery_right_link">
    <inertial>
      <origin
        xyz="-3.826065107051E-07 8.65721453095908E-05 0.0322499971323714"
        rpy="0 0 0" />
      <mass
        value="2.5145" />
      <inertia
        ixx="0.00258294"
        ixy="-7.81e-06"
        ixz="0"
        iyy="0.00560653"
        iyz="0"
        izz="0.00642109" />
    </inertial>
    <visual>
      <origin
        xyz="0 0 0"
        rpy="0 0 0" />
      <geometry>
        <mesh
          filename="package://eddiebot_gazebo/meshes/battery_right_link.STL" />
      </geometry>
      <material name ="black"/>
    </visual>
  </link>
  <joint name="battery_right_joint"
    type="fixed">
    <origin
      xyz="-0.006876 0.0454279216675194 -0.032"
      rpy="0 0 0" />
    <parent
      link="base_link" />
    <child
      link="battery_right_link" />
    <axis
      xyz="0 0 0" />
  </joint>
  <link name="battery_left_link">
    <inertial>
      <origin
        xyz="-3.82608826103407E-07 -2.41552581282251E-06 0.0325000028300059"
        rpy="0 0 0" />
      <mass
        value="2.5145" />
      <inertia
        ixx="0.00258294"
        ixy="7.81e-06"
        ixz="0.0"
        iyy="0.00560653"
        iyz="0.0"
        izz="0.00642109" />
    </inertial>
    <visual>
      <origin
        xyz="0 0 0"
        rpy="0 0 0" />
      <geometry>
        <mesh
          filename="package://eddiebot_gazebo/meshes/battery_left_link.STL" />
      </geometry>
      <material name ="black"/>
    </visual>
  </link>
  <joint name="battery_left_joint"
    type="fixed">
    <origin
      xyz="-0.00657600000000001 -0.0452620783324806 -0.032"
      rpy="0 0 0" />
    <parent
      link="base_link" />
    <child
      link="battery_left_link" />
    <axis
      xyz="0 0 0" />
  </joint>
  
 
  <link name="screen_case_link">
    <inertial>
      <origin
        xyz="0.00999443346163434 -0.0018961166873752 0.0682350661912288"
        rpy="0 0 0" />
      <mass
        value="0.403" />
        <inertia
          ixx="0.00003227"
          ixy="0.0"
          ixz="0.0"
          iyy="0.00003227"
          iyz="0.0"
          izz="0.00002691" />
    </inertial>
    <visual>
      <origin
        xyz="0 0 0"
        rpy="0 0 0" />
      <geometry>
        <mesh
          filename="package://eddiebot_gazebo/meshes/screen_case_link.STL" />
      </geometry>
      <material name="red"/>
    </visual>
    <collision>
      <origin
        xyz="0 0 0"
        rpy="0 0 0" />
      <geometry>
        <mesh
          filename="package://eddiebot_gazebo/meshes/screen_case_link.STL" />
      </geometry>
    </collision>
  </link>
  <joint name="screen_case_joint" type="fixed">
    <origin
      xyz="0.00475 -0.000999999997519367 0.148601341910205"
      rpy="0 0 0" />
    <parent
      link="kinect_plate_link" />
    <child
      link="screen_case_link" />
    <axis
      xyz="0 1 0" />
  </joint>

  <link name="screen_link">
    <visual>
      <origin
        xyz="0 0 0"
        rpy="0 0 0" />
      <geometry>
        <mesh
          filename="package://eddiebot_gazebo/meshes/screen_link.STL" />
      </geometry>
      <material name="black"/>
    </visual>
  </link>
  <joint name="screen_joint"
    type="fixed">
    <origin
      xyz="0.0045 0 0.0154"
      rpy="3.1416 0 1.5708" />
    <parent
      link="screen_case_link" />
    <child
      link="screen_link" />
    <axis
      xyz="0 0 1" />
  </joint>

  <!-- Main wheels -->
  <!-- Wheel right -->
   <link name="wheel_right_link">
    <inertial>
      <origin
        xyz="-1.66533453693773E-16 6.50521303491303E-18 0.0124886849718492"
        rpy="0 0 0" />
      <mass
        value="0.388" />
      <inertia
        ixx="0.00065987"
        ixy="0"
        ixz="0"
        iyy="0.00065987"
        iyz="0"
        izz="0.00126426" />
    </inertial>
    <visual>
      <origin
        xyz="0 0 0"
        rpy="0 0 0" />
        <geometry>
          <mesh
            filename="package://eddiebot_gazebo/meshes/wheel_right_link.STL" />
        </geometry>
      <material name ="black"/>
    </visual>
    <collision>
      <origin
        xyz="0 0 0"
        rpy="0 0 0" />
      <geometry>
        <cylinder radius="0.0765" length="0.0304"/>
      </geometry>
    </collision>
  </link>

  <joint name="wheel_right_joint"
    type="continuous">
    <origin
      xyz="0.0132060756317932 -0.08677 0.0415"
      rpy="1.5707963267949 1.5707963267949 3.14159265358979" />
    <parent
      link="motor_right_link" />
    <child
      link="wheel_right_link" />
    <axis
      xyz="0 0 1" />
    <dynamics
      damping="0"
      friction="0" />
  </joint>

  <!-- Wheel left -->
  <link name="wheel_left_link">
    <inertial>
      <origin
        xyz="3.05311331771918E-16 -1.3834419720915E-16 0.0124886849718492"
        rpy="0 0 0" />
      <mass
        value="0.388" />
      <inertia
        ixx="0.00065987"
        ixy="0"
        ixz="0"
        iyy="0.00065987"
        iyz="0"
        izz="0.00126426" />
    </inertial>
    <visual>
      <origin
        xyz="0 0 0"
        rpy="0 0 0" />
      <geometry>
        <mesh
          filename="package://eddiebot_gazebo/meshes/wheel_left_link.STL" />
      </geometry>
      <material
        name="black">
      </material>
    </visual>
    <collision>
      <origin
        xyz="0 0 0"
        rpy="0 0 0" />
      <geometry>
        <cylinder radius="0.0765" length="0.0304"/>
      </geometry>
    </collision>
  </link>
  
  <joint name="wheel_left_joint"
    type="continuous"> 
    <origin
      xyz="0.0132060756317932 0.08677 0.0415"
      rpy="-1.5707963267949 -1.5707963267949 3.14159265358979" />
    <parent
      link="motor_left_link" />
    <child
      link="wheel_left_link" />
    <axis
      xyz="0 0 -1" />
    <dynamics
      damping="0"
      friction="0" />
  </joint>

  <!-- Caster wheels -->
  <!-- Wheels rear caster -->
  <link name="wheels_rear_caster_link">
    <inertial>
      <origin
        xyz="-9.07934302185609E-08 -1.14285528513003E-07 1.36766179853476E-07"
        rpy="0 0 0" />
      <mass
        value="0.038" />
      <inertia
        ixx="0.00003227"
        ixy="0.00000000"
        ixz="0.00000000"
        iyy="0.00003227"
        iyz="0.00000000"
        izz="0.00002691" />
    </inertial>
    <visual>
      <origin
        xyz="0 0 0"
        rpy="0 0 0" />
      <geometry>
        <mesh
          filename="package://eddiebot_gazebo/meshes/wheels_rear_caster_link.STL" />
      </geometry>
      <material name="black"/>
    </visual>
    <collision>
      <origin
        xyz="0 0 0"
        rpy="0 0 0" />
      <geometry>
        <cylinder radius="0.03696" length="0.06297"/>
      </geometry>
    </collision>
  </link>

  <joint name="wheels_rear_caster_joint"
    type="continuous">
    <origin
      xyz="0 0.032344678103671 0.041525"
      rpy="-1.5707963267949 0 1.5707963267949" />
    <parent
      link="base_rear_caster_link" />
    <child
      link="wheels_rear_caster_link" />
      <axis
        xyz="0 0 1" />
    <dynamics
      damping="0"
      friction="0" />
  </joint>

  <!-- Wheels front caster -->
  <link name="wheels_front_caster_link">
    <inertial>
      <origin
        xyz="-9.07934300520274E-08 -1.14285528568514E-07 1.36766177948749E-07"
        rpy="0 0 0" />
      <mass
        value="0.038" />
      <inertia
        ixx="0.00003227"
        ixy="0.00000000"
        ixz="0.00000000"
        iyy="0.00003226"
        iyz="0.00000000"
        izz="0.00002691" />
    </inertial>
    <visual>
      <origin
        xyz="0 0 0"
        rpy="0 0 0" />
      <geometry>
        <mesh
          filename="package://eddiebot_gazebo/meshes/wheels_rear_caster_link.STL" />
      </geometry>
      <material name="black"/>
    </visual>
    <collision>
      <origin
        xyz="0 0 0"
        rpy="0 0 0" />
      <geometry>
          <cylinder radius="0.03696" length="0.06297"/>
      </geometry>
    </collision>
  </link>

  <joint name="wheels_front_caster_joint"
    type="continuous">
    <limit effort="100" velocity="10"/>
    <origin
      xyz="-0.001 -0.0323446781036711 0.0415249999999999"
      rpy="-1.5707963267949 0 1.54020690641159" />
    <parent
      link="base_front_caster_link" />
    <child
      link="wheels_front_caster_link"/>
    <axis
      xyz="0 0 1" />
    <dynamics
    damping="0"
    friction="0" />
  </joint>

  <!-- Caster -->
  <link name="base_rear_caster_link">
    <inertial>
      <origin
        xyz="2.46370895906622E-10 0.0243123370668157 0.0165207797650175"
        rpy="0 0 0" />
      <mass
        value="0.076" />
      <inertia
        ixx="0.00003100"
        ixy="0.00000000"
        ixz="0.00000000"
        iyy="0.00002130"
        iyz="-0.00000933"
        izz="0.00001206" />
    </inertial>
    <visual>
      <origin
        xyz="0 0 0"
        rpy="0 0 0" />
      <geometry>
        <mesh
          filename="package://eddiebot_gazebo/meshes/base_rear_caster_link.STL" />
      </geometry>
      <material name ="orange"/>
    </visual>
  </link>
  <joint name="base_rear_caster_joint"
    type="continuous">
    <origin
      xyz="-0.200793924368207 0 0.0114749999986939"
      rpy="3.14159265358979 0 -1.5707963267949" />
    <parent
      link="base_link" />
    <child
      link="base_rear_caster_link" />
    <axis
      xyz="0 0 -1" />
  </joint>
  <link name="base_front_caster_link">
    <inertial>
      <origin
        xyz="-0.00074358459420179 -0.024300963323452 0.016520779818389"
        rpy="0 0 0" />
      <mass
        value="0.076" />
      <inertia
        ixx="0.00003099"
        ixy="-0.00000030"
        ixz="0.00000029"
        iyy="0.00002131"
        iyz="0.00000932"
        izz="0.00001206"  />
    </inertial>
    <visual>
      <origin
        xyz="0 0 0"
        rpy="0 0 0" />
      <geometry>
        <mesh
          filename="package://eddiebot_gazebo/meshes/base_front_caster_link.STL" />
      </geometry>
      <material name="orange"/>
    </visual>
  </link>
  <joint name="base_front_caster_joint"
    type="continuous">
    <origin
      xyz="0.187206075631793 0 0.0114749999986939"
      rpy="-3.14159265358979 0 -1.60138574717821" />
    <parent
      link="base_link" />
    <child
      link="base_front_caster_link" />
    <axis
      xyz="0 0 -1" />
  </joint>

  <!-- IMU -->
  <joint name="imu_joint" type="fixed">
    <parent link="base_link"/>
    <child link="imu_link"/>
    <origin xyz="-0.032 0 0.068" rpy="0 0 0"/>
  </joint>
  <link name="imu_link"/>

  <!-- LIDAR -->
  <!--
  <joint name="laser_joint" type="fixed">
    <parent link="base_top_link"/>
    <child link="laser_frame"/>
    <origin xyz="0 0 0.125" rpy="0 3.14 0"/>
  </joint>

<link name="laser_frame">
    <visual>
        <origin xyz="0 0 0" rpy="-1.57 0 0"/>
        <geometry>
          <mesh
          filename="package://eddiebot_gazebo/meshes/rplidar.stl" scale="0.0005 0.0005 0.0005"/>
          
        </geometry>
        <material name="dark"/>
    </visual>
    <collision>
        <geometry>
            <cylinder radius="0.05" length="0.04"/>
        </geometry>
    </collision>
    <xacro:inertial_cylinder mass="0.1" length="0.04" radius="0.05">
        <origin xyz="0 0 0" rpy="0 0 0"/>
    </xacro:inertial_cylinder>
</link>
-->
<!-- Kinect -->
<!-- 
<link name="pos_kinect_Link"/>
<joint name="pos_kinect_joint"
  type="fixed">
  <origin
    xyz="0.01 -0.00100184102795236 0.36199"
    rpy="0 0 0" />
  <parent
    link="kinect_plate_link" />
  <child
    link="pos_kinect_Link" />
  <axis
    xyz="0 0 0" />
</joint>
  <xacro:property name="cam_px" value="0" />
  <xacro:property name="cam_py" value="0" /> 
  <xacro:property name="cam_pz" value="0" />
	<xacro:property name="cam_or" value="0" />
	<xacro:property name="cam_op" value="0" />
	<xacro:property name="cam_oy" value="0" />

  <xacro:include filename="$(find eddiebot_gazebo)/urdf/kinect.urdf.xacro" />
  <xacro:sensor_kinect parent="pos_kinect_Link" cam_px="${cam_px}" cam_py="${cam_py}" cam_pz="${cam_pz}" cam_or="${cam_or}" cam_op="${cam_op}" cam_oy="${cam_oy}"/>
  
 
  -->

  <!-- GAZEBO frictions -->
<!--
  <transmission name="left_trans">
    <type>transmission_interface/SimpleTransmission</type>
    <joint name="wheel_left_joint">
      <hardwareInterface>hardware_interface/VelocityJointInterface</hardwareInterface>
    </joint>
    <actuator name="left_motor">
      <hardwareInterface>hardware_interface/VelocityJointInterface</hardwareInterface>
      <mechanicalReduction>1</mechanicalReduction>
    </actuator>
  </transmission>

  <transmission name="right_trans">
    <type>transmission_interface/SimpleTransmission</type>
    <joint name="wheel_right_joint">
      <hardwareInterface>hardware_interface/VelocityJointInterface</hardwareInterface>
    </joint>
    <actuator name="right_motor">
      <hardwareInterface>hardware_interface/VelocityJointInterface</hardwareInterface>
      <mechanicalReduction>1</mechanicalReduction>
    </actuator>
  </transmission>
-->

  <gazebo reference="wheel_left_link">
    <mu1>0.9</mu1>
    <mu2>0.9</mu2>
    <kp>1000000.0</kp>
    <kd>100.0</kd>
    
    <minDepth>0.001</minDepth>
    <maxVel>1.0</maxVel>

  </gazebo>

  <gazebo reference="wheel_right_link">
    <mu1>0.9</mu1>
    <mu2>0.9</mu2>
    <kp>1000000.0</kp>
    <kd>100.0</kd>
   
    <minDepth>0.001</minDepth>
    <maxVel>1.0</maxVel>

  </gazebo>

  <gazebo reference="base_front_caster_link">
    <mu1>0.1</mu1>
    <mu2>0.1</mu2>
    <kp>1000000.0</kp>
    <kd>100.0</kd>
    <minDepth>0.001</minDepth>
    <maxVel>1.0</maxVel>
 
  </gazebo>

  <gazebo reference="base_rear_caster_link">
    <mu1>0.1</mu1>
    <mu2>0.1</mu2>
    <kp>1000000.0</kp>
    <kd>100.0</kd>
    <minDepth>0.001</minDepth>
    <maxVel>1.0</maxVel>
    
  </gazebo>

  <gazebo reference="wheels_front_caster_link">
    <mu1>0.1</mu1>
    <mu2>0.1</mu2>
    <kp>1000000.0</kp>
    <kd>100.0</kd>
    <minDepth>0.001</minDepth>
    <maxVel>1.0</maxVel>
 
  </gazebo>

  <gazebo reference="wheels_rear_caster_link">
    <mu1>0.1</mu1>
    <mu2>0.1</mu2>
    <kp>1000000.0</kp>
    <kd>100.0</kd>
    <minDepth>0.001</minDepth>
    <maxVel>1.0</maxVel>

  </gazebo>

  <ros2_control name="eddiebot_system" type="system">
    <hardware>
      <plugin>gz_ros2_control/GazeboSystem</plugin>
    </hardware>
    <joint name="wheel_left_joint">
      <command_interface name="velocity"/>
      <state_interface name="position"/>
      <state_interface name="velocity"/>
    </joint>
    <joint name="wheel_right_joint">
      <command_interface name="velocity"/>
      <state_interface name="position"/>
      <state_interface name="velocity"/>
    </joint>
  </ros2_control>
</robot>